Workbook

Sheet LIBRO DIARIO
B1: LIBRO DIARIO
B3: Cálculo Auxiliar en Esquema T | G3: FORMATO DEL LIBRO DIARIO
B4: DEBE | D4: HABER | G4: NRO | H4: FECHA | I4: CUENTAS CONTABLES | J4: DEBE | K4: HABER | P4: BG:Balance General
B5: CAJA | C5: 1000000 | D5: PASIVO | E5: 0 | G5: 1 | H5: 46147 | I5: CAJA | J5: 1000000 | P5: ER:Estado de Resultado
B6: BANCO GNB CTA CTE | C6: 45000000 | D6: CAPITAL | E6: =C8 -> 46000000 | I6: BANCO GNB CTA CTE | J6: 46000000
I7: CAPITAL | K7: 47000000
B8: ACTIVO | C8: =SUM(C5:C6) -> 46000000 | I8: ASIENTO DE APERTURA
I9: EMPRESA JORGE SARABIA | J9: =SUM(J5:J8) -> 47000000 | K9: =SUM(K7:K8) -> 47000000
B11: DEBE | D11: HABER | G11: 2 | H11: 46151 | I11: MERCADERIAS | J11: =C12 -> 3636363.6
B12: MERCADERIAS | C12: =C17/1.1 -> 3636363.6 | D12: DOCUMENTOS A PAGAR | E12: =C17 -> 4000000 | I12: IVA CF 10% | J12: =C13 -> 363636.36
B13: IVA CF 10% | C13: =C17/11 -> 363636.36 | D13: PASIVO | E13: =E12 -> 4000000 | I13: DOCUMENTOS A PAGAR | K13: 4000000
B14: ACTIVO | C14: =SUM(C12:C13) -> 4000000 | I14: COMPRA DE MOCHILAS SEGÚN
I15: FACT.036589 C/PAGARE | J15: =SUM(J11:J14) -> 4000000 | K15: =SUM(K13:K14) -> 4000000
B16: COST. UNIT | C16: 400000 | D16: CANT | E16: 10
B17: COSTO TOTAL | C17: =C16*E16 -> 4000000 | G17: 3 | H17: 46152 | I17: HONORARIOS PROFESIONALES | J17: =C19 -> 3272727.3
B18: DEBE | D18: HABER | I18: IVA CF 10% | J18: =C20 -> 327272.73
B19: HONORARIOS PROFESIONALES | C19: =3600000/1.1 -> 3272727.3 | D19: BANCO GNB CTA CTE | E19: 3600000 | I19: BANCO GNB CTA CTE | K19: =E19 -> 3600000
B20: IVA CF 10% | C20: =3600000/11 -> 327272.73 | I20: PAGO A CONTADOR, SEGÚN
B21: ACTIVO | C21: =SUM(C19:C20) -> 3600000 | D21: PASIVO | E21: =SUM(E19:E20) -> 3600000 | I21: FACTURA A CONTADO
G23: 4 | H23: 46154 | I23: SERVICIOS BASICOS | J23: =C24 -> 545454.55
B24: SERVICIOS BASICOS | C24: =600000/1.1 -> 545454.55 | D24: BANCO GNB CTA CTE | E24: 600000 | I24: IVA CF 10% | J24: =C25 -> 54545.455
B25: IVA CF 10% | C25: =600000/11 -> 54545.455 | I25: BANCO GNB CTA CTE | K25: =E24 -> 600000
B26: ACTIVO | C26: =SUM(C24:C25) -> 600000 | D26: PASIVO | E26: =SUM(E24:E25) -> 600000 | I26: PAGO DE SERVICIO ANDE
B27: 5.
A28: VENTA | G28: 5 | H28: 46159 | I28: CAJA | J28: 1375000
A29: =5*550000 -> 2750000 | B29: CAJA | C29: =A29*50% -> 1375000 | D29: VENTA DE MERCADERIAS | E29: =A29/1.1 -> 2500000 | I29: DOCUMENTO A COBRAR | J29: 1375000
B30: DOCUMENTO A COBRAR | C30: =C29 -> 1375000 | D30: IVA DF 10% | E30: =A29/11 -> 250000 | I30: INTERES A VENCER | J30: 8021
B31: INTERES A VENCER | C31: =(C30*30*7)/(360*100) -> 8020.8333 | D31: INTERES A PAGAR | E31: =C31 -> 8020.8333 | I31: VENTA DE MERCADERIA | K31: 2500000
C32: =SUM(C29:C31) -> 2758020.8 | E32: =SUM(E29:E31) -> 2758020.8 | I32: IVA DF 10% | K32: 250000
I33: INTERES A PAGAR | K33: 8021
A34: COSTO | I34: VENTA DE MERCADERIAS | J34: =SUM(J28:J33) -> 2758021 | K34: =SUM(K31:K33) -> 2758021
B35: COSTO DE VENTAS | C35: =C39 -> 1818181.8 | D35: MERCADERIAS | E35: =C35 -> 1818181.8
G36: 6 | H36: 46159 | I36: COSTO DE VENTAS | J36: 1818182
I37: MERCADERIAS | K37: =J36 -> 1818182
B38: COSTO=UNI.VEND * PRECIOCOMPRASIN IVA | I38: COSTEO DE VENTAS | J38: =SUM(J36:J37) -> 1818182 | K38: =SUM(K37) -> 1818182
B39: COSTO | C39: =C40*C41 -> 1818181.8
B40: UNI.VEND | C40: 5 | G40: 7 | H40: 46160 | I40: BANCO CTA CTE | J40: 1375000
B41: PC S/IVA | C41: =C16/1.1 -> 363636.36 | I41: CAJA | K41: =J40 -> 1375000
I42: DEPOSITO EN BANCO DE
B43: 6. | I43: RECAUDACION DIA ANTERIOR
...

Sheet LIBRO MAYOR
A1: FORMATO DEL LIBRO MAYOR
A3: FOLIO: | B3: 1 | C3: CUENTA: | D3: CAJA
A4: NRO | B4: FECHA | C4: DESCRIPCIÓN | D4: DEBE | E4: HABER | F4: SALDO
A5: ='LIBRO DIARIO'!G5 -> 1 | B5: ='LIBRO DIARIO'!H5 -> 46147 | C5: ='LIBRO DIARIO'!I8 -> ASIENTO DE APERTURA | D5: ='LIBRO DIARIO'!J5 -> 1000000 | F5: =D5 -> 1000000
A6: 5 | B6: ='LIBRO DIARIO'!H28 -> 46159 | C6: ='LIBRO DIARIO'!I34 -> VENTA DE MERCADERIAS | D6: ='LIBRO DIARIO'!J28 -> 1375000 | F6: =F5+D6 -> 2375000
A7: 7 | B7: ='LIBRO DIARIO'!H40 -> 46160 | C7: DEPOSITO EN BANCO | E7: =D6 -> 1375000 | F7: =F6-E7 -> 1000000
D8: =SUM(D5:D7) -> 2375000 | E8: =SUM(E7) -> 1375000
A11: FOLIO: | B11: 2 | C11: CUENTA: | D11: BANCO GNB CTA CTE
A12: NRO | B12: FECHA | C12: DESCRIPCIÓN | D12: DEBE | E12: HABER | F12: SALDO
A13: ='LIBRO DIARIO'!G5 -> 1 | B13: ='LIBRO DIARIO'!H5 -> 46147 | C13: =C5 -> ASIENTO DE APERTURA | D13: ='LIBRO DIARIO'!J6 -> 46000000 | F13: =D13 -> 46000000
A14: 3 | B14: ='LIBRO DIARIO'!H17 -> 46152 | C14: ='LIBRO DIARIO'!I20 -> PAGO A CONTADOR, SEGÚN | E14: ='LIBRO DIARIO'!K19 -> 3600000 | F14: =F13-E14 -> 42400000
A15: ='LIBRO DIARIO'!G23 -> 4 | B15: ='LIBRO DIARIO'!H23 -> 46154 | C15: ='LIBRO DIARIO'!I26 -> PAGO DE SERVICIO ANDE | E15: ='LIBRO DIARIO'!K25 -> 600000 | F15: =F14-E15 -> 41800000
A16: ='LIBRO DIARIO'!G40 -> 7 | B16: ='LIBRO DIARIO'!H40 -> 46160 | C16: ='LIBRO DIARIO'!I42 -> DEPOSITO EN BANCO DE | D16: ='LIBRO DIARIO'!J40 -> 1375000 | F16: =F15+D16 -> 43175000
D17: =SUM(D13:D16) -> 47375000 | E17: =SUM(E14:E16) -> 4200000
A19: FOLIO: | B19: 3 | C19: CUENTA: | D19: CAPITAL
A20: NRO | B20: FECHA | C20: DESCRIPCIÓN | D20: DEBE | E20: HABER | F20: SALDO
A21: 1 | B21: =B13 -> 46147 | C21: =C13 -> ASIENTO DE APERTURA | E21: ='LIBRO DIARIO'!K7 -> 47000000 | F21: =E21 -> 47000000
D24: 0 | E24: =E21 -> 47000000 | F24: =E24 -> 47000000
A27: FOLIO: | B27: 4 | C27: CUENTA: | D27: MERCADERIAS
A28: NRO | B28: FECHA | C28: DESCRIPCIÓN | D28: DEBE | E28: HABER | F28: SALDO
A29: ='LIBRO DIARIO'!G11 -> 2 | B29: ='LIBRO DIARIO'!H11 -> 46151 | C29: ='LIBRO DIARIO'!I14 -> COMPRA DE MOCHILAS SEGÚN | D29: ='LIBRO DIARIO'!J11 -> 3636363.6 | F29: =D29 -> 3636363.6
A30: ='LIBRO DIARIO'!G36 -> 6 | B30: ='LIBRO DIARIO'!H36 -> 46159 | C30: ='LIBRO DIARIO'!I38 -> COSTEO DE VENTAS | E30: ='LIBRO DIARIO'!K37 -> 1818182 | F30: =F29-E30 -> 1818181.6
D32: =D29 -> 3636363.6 | E32: =E30 -> 1818182
A35: FOLIO: | B35: 5 | C35: CUENTA: | D35: IVA CF 10%
A36: NRO | B36: FECHA | C36: DESCRIPCIÓN | D36: DEBE | E36: HABER | F36: SALDO
A37: 2 | B37: 46151 | C37: ='LIBRO DIARIO'!I14 -> COMPRA DE MOCHILAS SEGÚN | D37: ='LIBRO DIARIO'!J12 -> 363636.36 | F37: =D37 -> 363636.36
A38: ='LIBRO DIARIO'!G17 -> 3 | B38: ='LIBRO DIARIO'!H17 -> 46152 | C38: ='LIBRO DIARIO'!I20 -> PAGO A CONTADOR, SEGÚN | D38: ='LIBRO DIARIO'!J18 -> 327272.73 | F38: =F37+D38 -> 690909.09
A39: 4 | B39: ='LIBRO DIARIO'!H23 -> 46154 | C39: ='LIBRO DIARIO'!I26 -> PAGO DE SERVICIO ANDE | D39: ='LIBRO DIARIO'!J24 -> 54545.455 | F39: =F38+D39 -> 745454.55
D40: =SUM(D37:D39) -> 745454.55 | E40: 0
A43: FOLIO: | B43: 6 | C43: CUENTA: | D43: DOCUMENTOS A PAGAR
A44: NRO | B44: FECHA | C44: DESCRIPCIÓN | D44: DEBE | E44: HABER | F44: SALDO
A45: 2 | B45: 46151 | C45: ='LIBRO DIARIO'!I14 -> COMPRA DE MOCHILAS SEGÚN | E45: ='LIBRO DIARIO'!K13 -> 4000000 | F45: =E45 -> 4000000
D48: 0 | E48: =E45 -> 4000000 | F48: =E48 -> 4000000
A51: FOLIO: | B51: 7 | C51: CUENTA: | D51: HONORARIOS PROFESIONALES
A52: NRO | B52: FECHA | C52: DESCRIPCIÓN | D52: DEBE | E52: HABER | F52: SALDO
A53: 3 | B53: 46152 | C53: ='LIBRO DIARIO'!I20 -> PAGO A CONTADOR, SEGÚN | D53: ='LIBRO DIARIO'!J17 -> 3272727.3 | F53: =D53 -> 3272727.3
D56: =D53 -> 3272727.3 | E56: 0 | F56: =F53 -> 3272727.3
A59: FOLIO: | B59: 8 | C59: CUENTA: | D59: SERVICIOS BASICOS
A60: NRO | B60: FECHA | C60: DESCRIPCIÓN | D60: DEBE | E60: HABER | F60: SALDO
A61: ='LIBRO DIARIO'!G23 -> 4 | B61: ='LIBRO DIARIO'!H23 -> 46154 | C61: ='LIBRO DIARIO'!I26 -> PAGO DE SERVICIO ANDE | D61: ='LIBRO DIARIO'!J23 -> 545454.55 | F61: =D61 -> 545454.55
...

Sheet BG _ER
A1: BALANCE DE COMPROBACIÓN DE SUMAS Y SALDOS - BALANCE GENERAL & ESTADO DE RESULTADOS
A3: Nro. | B3: CUENTA CONTABLE | C3: SUMAS | E3: SALDOS | G3: BALANCE GENERAL | I3: ESTADO DE RESULTADOS
C4: DEBE | D4: HABER | E4: DEUDOR | F4: ACREEDOR | G4: ACTIVO | H4: PASIVO/PN | I4: RES. NEGATIVO | J4: RES. POSITIVO
A5: 1 | B5: CAJA | C5: ='LIBRO MAYOR'!D8 -> 2375000 | D5: ='LIBRO MAYOR'!E8 -> 1375000 | E5: ='LIBRO MAYOR'!F7 -> 1000000 | G5: =E5 -> 1000000
A6: 2 | B6: ='LIBRO MAYOR'!D11 -> BANCO GNB CTA CTE | C6: ='LIBRO MAYOR'!D17 -> 47375000 | D6: ='LIBRO MAYOR'!E17 -> 4200000 | E6: ='LIBRO MAYOR'!F16 -> 43175000 | G6: =E6 -> 43175000
A7: 3 | B7: CAPITAL | C7: 0 | D7: ='LIBRO MAYOR'!E24 -> 47000000 | F7: ='LIBRO MAYOR'!F24 -> 47000000 | H7: =F7 -> 47000000
A8: 4 | B8: MERCADERIAS | C8: ='LIBRO MAYOR'!D32 -> 3636363.6 | D8: ='LIBRO MAYOR'!E32 -> 1818182 | E8: ='LIBRO MAYOR'!F30 -> 1818181.6 | G8: =E8 -> 1818181.6
A9: 5 | B9: IVA CF 10% | C9: ='LIBRO MAYOR'!D40 -> 745454.55 | D9: 0 | E9: ='LIBRO MAYOR'!F39 -> 745454.55 | G9: =E9 -> 745454.55
A10: 6 | B10: ='LIBRO MAYOR'!D43 -> DOCUMENTOS A PAGAR | C10: 0 | D10: ='LIBRO MAYOR'!E48 -> 4000000 | F10: ='LIBRO MAYOR'!F48 -> 4000000 | H10: =F10 -> 4000000
A11: 7 | B11: ='LIBRO MAYOR'!D51 -> HONORARIOS PROFESIONALES | C11: ='LIBRO MAYOR'!D56 -> 3272727.3 | D11: 0 | E11: =C11 -> 3272727.3 | I11: =E11 -> 3272727.3
A12: 8 | B12: ='LIBRO MAYOR'!D59 -> SERVICIOS BASICOS | C12: ='LIBRO MAYOR'!D64 -> 545454.55 | E12: =C12 -> 545454.55 | H12: =E12 -> 545454.55
A13: 9 | B13: ='LIBRO MAYOR'!D67 -> DOCUMENTO A COBRAR | C13: ='LIBRO MAYOR'!D72 -> 1375000 | D13: 0 | E13: ='LIBRO MAYOR'!F72 -> 1375000 | G13: =E13 -> 1375000
A14: 10 | B14: ='LIBRO MAYOR'!D75 -> INTERES A VENCER | C14: ='LIBRO MAYOR'!D80 -> 8021 | D14: 0 | E14: =C14 -> 8021 | G14: =E14 -> 8021
A15: 11 | B15: ='LIBRO MAYOR'!D83 -> VENTA DE MERCADERIAS | C15: 0 | D15: ='LIBRO MAYOR'!E85 -> 2500000 | F15: =D15 -> 2500000 | J15: =F15 -> 2500000
A16: 12 | B16: ='LIBRO MAYOR'!D91 -> IVA DF 10% | C16: 0 | D16: ='LIBRO MAYOR'!E93 -> 250000 | F16: =D16 -> 250000 | H16: =F16 -> 250000
A17: 13 | B17: ='LIBRO MAYOR'!D99 -> INTERES A PAGAR | C17: 0 | D17: ='LIBRO MAYOR'!E101 -> 8021 | F17: =D17 -> 8021 | H17: =F17 -> 8021
A18: 14 | B18: ='LIBRO MAYOR'!D107 -> COSTO DE VENTAS | C18: ='LIBRO MAYOR'!D112 -> 1818182 | D18: 0 | E18: ='LIBRO MAYOR'!F112 -> 1818182 | I18: =E18 -> 1818182
A19: 15
A20: 16
A21: 17
C22: =SUM(C5:C21) -> 61151203 | D22: =SUM(D5:D21) -> 61151203 | E22: =SUM(E5:E18) -> 53758021 | F22: =SUM(F7:F19) -> 53758021 | G22: =SUM(G5:G21) -> 48121657 | H22: =SUM(H5:H20) -> 51803476 | I22: =SUM(I10:I21) -> 5090909.3 | J22: =SUM(J14:J15) -> 2500000
G23: =H22-G22 -> 3681818.4 | J23: =I22-J22 -> 2590909.3 | K23: perdida
C24: =SUM(C22:C23) -> 61151203 | D24: =SUM(D22:D23) -> 61151203 | E24: =SUM(E22:E23) -> 53758021 | F24: =SUM(F22:F23) -> 53758021 | G24: =SUM(G22:G23) -> 51803476 | H24: =SUM(H22:H23) -> 51803476 | I24: =SUM(I22:I23) -> 5090909.3 | J24: =SUM(J22:J23) -> 5090909.3
C27: PASIVO | D27: =H22-D28 -> 4803475.5
C28: PATRIMONIO | D28: =D7 -> 47000000
