Workbook

Sheet LIBRO DIARIO
B1: LIBRO DIARIO
B3: Cálculo Auxiliar en Esquema T | G3: FORMATO DEL LIBRO DIARIO
B4: DEBE | D4: HABER | G4: NRO | H4: FECHA | I4: CUENTAS CONTABLES | J4: DEBE | K4: HABER
B5: Fondo Fijo | C5: 2500000 | D5: Prestamos Bancarios | E5: 200000000 | G5: 1 | H5: 45413 | I5: Fondo Fijo | J5: 2500000
B6: Banco GNB SA CTA CTE | C6: 450000000 | D6: Interes a Pagar | E6: =(E5*180*12.5)/(365*100) -> 12328767 | H6: 45413 | I6: Banco GNB CTA CTE | J6: 450000000
B7: Banco ITAU SA PLAZO FIJO | C7: 100000000 | D7: TOTAL PASIVO | E7: =E6+E5 -> 2.1232877e+08 | H7: 45413 | I7: Banco Itaú S.A | J7: 100000000
B8: Documentos a Cobrar | C8: 1300000 | D8: Capital | E8: =C10-E7 -> 3.4147123e+08 | H8: 45413 | I8: Documentos a Cobrar | J8: 1300000
D9: PAS+P.NETO | E9: =SUM(E7:E8) -> 553800000 | H9: 45413 | I9: Prestamos Bancarios | K9: 200000000
B10: TOTAL ACTIVO | C10: =SUM(C5:C8) -> 553800000 | I10: Interes a Pagar | K10: =E6 -> 12328767
I11: Capital | K11: =E8 -> 3.4147123e+08
I12: APERTURA COMERCIAL EN FECHA
B13: DEBE | D13: HABER
B14: Muebles y Equipos | C14: =E14/1.1 -> 2409090.9 | D14: Banco GNB CTA CTE | E14: 2650000 | G14: 2 | H14: 45414 | I14: Muebles y Equipos | J14: =C14 -> 2409090.9
B15: IVA CF 10% | C15: =E14/11 -> 240909.09 | H15: 45414 | I15: IVA CF 10% | J15: =C15 -> 240909.09
H16: 45414 | I16: Banco GNB SA CTA CTE | K16: =E14 -> 2650000
B17: entrada | D17: salida | I17: Compra de Mobiliarios
B18: DEBE | D18: HABER
B19: Elementos de Transporte | C19: =E21/1.1 -> 42727273 | D19: Banco GNB SA CTE | E19: =E21/2 -> 23500000 | G19: 3 | H19: 45415 | I19: Elementos de Transporte | J19: =C19 -> 42727273
B20: IVA CF 10% | C20: =E21/11 -> 4272727.3 | D20: Documentos a Pagar | E20: =E21/2 -> 23500000 | H20: 45415 | I20: =B20 -> IVA CF 10% | J20: =C20 -> 4272727.3
E21: 47000000 | H21: 45415 | I21: =D19 -> Banco GNB SA CTE | K21: =E20 -> 23500000
H22: 45415 | I22: =D20 -> Documentos a Pagar | K22: =K21 -> 23500000
A23: Compra | B23: DEBE | D23: HABER | I23: COMPRA DE CAMIONETA
B24: Mercaderias | C24: =D31/1.1 -> 2.0409091e+08 | D24: Banco GNB SA CTA CTE | E24: 224500000
B25: IVA CF 10% | C25: =D31/11 -> 20409091 | G25: 4 | H25: 45416 | I25: =B24 -> Mercaderias | J25: =C24 -> 2.0409091e+08
H26: 45416 | I26: =B25 -> IVA CF 10% | J26: =C25 -> 20409091
H27: 45416 | I27: =D24 -> Banco GNB SA CTA CTE | K27: =E24 -> 224500000
C28: CADA UNO CON IVA | D28: TOTAL | I28: COMPRA DE MERCADERIAS
A29: 35 | B29: PSP | C29: 5900000 | D29: =35*C29 -> 206500000
A30: 30 | B30: PSR | C30: 600000 | D30: =30*C30 -> 18000000 | G30: 5 | H30: 45418 | I30: Banco GNB SA CTA CTE | J30: =89520000 -> 89520000
D31: =D30+D29 -> 224500000 | H31: 45418 | I31: DOCUMENTOS A COBRAR | J31: 134280000
A32: Venta | B32: DEBE | D32: HABER | H32: 45418 | I32: VENTA DE MERCADERIAS | K32: 203454545
A33: 0.4 | B33: Banco GNB SA CTA CTE | C33: =D39*40% -> 89520000 | D33: Venta de Mercaderias | E33: =D39/1.1 -> 2.0345455e+08 | H33: 45418 | I33: IVA DF 10% | K33: 20345455
A34: 0.6 | B34: Documentos a Cobrar | C34: =D39*A34 -> 134280000 | D34: IVA DF 10% | E34: =D39/11 -> 20345455 | I34: VENTA DE MERCADERIAS
C36: PRECIO DE VENTA UNITARIO | G36: 6 | H36: 45418 | I36: Costo de Ventas | J36: =C41 -> 172909091
A37: 30 | B37: PSP | C37: 6800000 | D37: =C37*A37 -> 204000000 | H37: 45418 | I37: Mercaderias | K37: =E41 -> 1.7290909e+08
A38: 22 | B38: PSR | C38: 900000 | D38: =A38*C38 -> 19800000 | I38: COSTEO SEGUN FICHA DE DEPOSITO
D39: =D38+D37 -> 223800000
A40: costo venta | B40: DEBE | D40: HABER | G40: 7 | H40: 45420 | I40: Mercaderias | J40: =C55 -> 56363636
B41: Costo de Ventas | C41: 172909091 | D41: Mercaderias | E41: =C51 -> 1.7290909e+08 | I41: Iva CF 10% | J41: =C56 -> 5636363.6
I42: Banco GNB SA CTA CTE | K42: =E55 -> 62000000
...

Sheet LIBRO MAYOR
A1: FORMATO DEL LIBRO MAYOR
A3: FOLIO: | B3: 1 | C3: CUENTA: | D3: ='LIBRO DIARIO'!I5 -> Fondo Fijo
A4: NRO | B4: FECHA | C4: DESCRIPCIÓN | D4: DEBE | E4: HABER | F4: SALDO
A5: 1 | B5: ='LIBRO DIARIO'!H5 -> 45413 | C5: ='LIBRO DIARIO'!I12 -> APERTURA COMERCIAL EN FECHA | D5: ='LIBRO DIARIO'!J5 -> 2500000
B8: sumas | C8: =D5 -> 2500000
A11: FOLIO: | B11: 2 | C11: CUENTA: | D11: Banco GNB SA CTA CTE
A12: NRO | B12: FECHA | C12: DESCRIPCIÓN | D12: DEBE | E12: HABER | F12: SALDO
A13: 1 | B13: =B5 -> 45413 | C13: =C5 -> APERTURA COMERCIAL EN FECHA | D13: 450000000 | F13: =D13 -> 450000000
A14: 2 | B14: 45414 | C14: Compra de Mobiliarios | E14: ='LIBRO DIARIO'!K16 -> 2650000 | F14: =F13-E14 -> 447350000
A15: 3 | B15: 45415 | C15: Compra de Camioneta | E15: 23500000 | F15: =F14-E15 -> 423850000
B16: 45418 | C16: Compra de Mercaderias | E16: ='LIBRO DIARIO'!K27 -> 224500000 | F16: =F15-E16 -> 199350000
B17: 45420 | C17: Venta de Mercaderias | D17: ='LIBRO DIARIO'!J30 -> 89520000 | F17: =F16+D17 -> 288870000
B18: 45420 | C18: Compra de Mercaderias | E18: ='LIBRO DIARIO'!K42 -> 62000000 | F18: =F17-E18 -> 226870000
B19: 45420 | C19: Venta de Mercaderias | D19: ='LIBRO DIARIO'!J45 -> 91700000 | F19: =F18+D19 -> 318570000
B20: 45421 | C20: Pago por Patente Comercial | E20: 500000 | F20: =F19-E20 -> 318070000
B21: 45424 | C21: ='LIBRO DIARIO'!I61 -> COMPRA DE PRODUCTOS DE LIMPIEZA | E21: 1320000 | F21: =F20-E21 -> 316750000
B22: 45427 | C22: ='LIBRO DIARIO'!I66 -> PAGO DE SERVICIOS DE INTERNET | E22: 980000 | F22: =F21-E22 -> 315770000
B23: 45432 | C23: ='LIBRO DIARIO'!I71 -> PAGO AL CONTADOR POR TRAMITES | E23: ='LIBRO DIARIO'!K70 -> 5080000 | F23: =F22-E23 -> 310690000
C24: SUMAS | D24: =SUM(D13:D23) -> 631220000 | E24: =SUM(E13:E23) -> 320530000
A26: FOLIO: | B26: 3 | C26: CUENTA: | D26: Banco ITAU S.A
A27: NRO | B27: FECHA | C27: DESCRIPCIÓN | D27: DEBE | E27: HABER | F27: SALDO
A28: 1 | B28: =B13 -> 45413 | C28: ='LIBRO DIARIO'!I12 -> APERTURA COMERCIAL EN FECHA | D28: ='LIBRO DIARIO'!J7 -> 100000000 | F28: =D28 -> 100000000
C31: SUMAS | D31: =D28 -> 100000000
A34: FOLIO: | B34: 4 | C34: CUENTA: | D34: Documentos a Cobrar
A35: NRO | B35: FECHA | C35: DESCRIPCIÓN | D35: DEBE | E35: HABER | F35: SALDO
A36: 1 | B36: =B28 -> 45413 | C36: ='LIBRO DIARIO'!I12 -> APERTURA COMERCIAL EN FECHA | D36: ='LIBRO DIARIO'!J8 -> 1300000 | F36: =D36 -> 1300000
A37: 5 | B37: 45416 | C37: ='LIBRO DIARIO'!I34 -> VENTA DE MERCADERIAS | D37: ='LIBRO DIARIO'!J31 -> 134280000 | F37: =D37+D36 -> 135580000
C39: SUMAS | D39: =SUM(D36:D38) -> 135580000
A42: FOLIO: | B42: 5 | C42: CUENTA: | D42: Prestamos Bancarios
A43: NRO | B43: FECHA | C43: DESCRIPCIÓN | D43: DEBE | E43: HABER | F43: SALDO
A44: 1 | B44: =B36 -> 45413 | C44: =C36 -> APERTURA COMERCIAL EN FECHA | E44: ='LIBRO DIARIO'!K9 -> 200000000 | F44: =E44 -> 200000000
C47: SUMAS | E47: =E44 -> 200000000
A50: FOLIO: | B50: 6 | C50: CUENTA: | D50: Interes a Pagar
A51: NRO | B51: FECHA | C51: DESCRIPCIÓN | D51: DEBE | E51: HABER | F51: SALDO
A52: 1 | B52: =B44 -> 45413 | C52: =C44 -> APERTURA COMERCIAL EN FECHA | E52: ='LIBRO DIARIO'!K10 -> 12328767 | F52: =E52 -> 12328767
C55: SUMAS | E55: =E52 -> 12328767
A58: FOLIO: | B58: 7 | C58: CUENTA: | D58: Capital
A59: NRO | B59: FECHA | C59: DESCRIPCIÓN | D59: DEBE | E59: HABER | F59: SALDO
A60: 1 | B60: =B52 -> 45413 | C60: =C52 -> APERTURA COMERCIAL EN FECHA | E60: ='LIBRO DIARIO'!K11 -> 3.4147123e+08 | F60: =E60 -> 3.4147123e+08
C63: SUMAS | E63: =E60 -> 3.4147123e+08
...

Sheet BG _ER
A1: BALANCE DE COMPROBACIÓN DE SUMAS Y SALDOS - BALANCE GENERAL & ESTADO DE RESULTADOS
A3: Nro. | B3: CUENTA CONTABLE | C3: SUMAS | E3: SALDOS | G3: BALANCE GENERAL | I3: ESTADO DE RESULTADOS
C4: DEBE | D4: HABER | E4: DEUDOR | F4: ACREEDOR | G4: ACTIVO | H4: PASIVO/PN | I4: RES. NEGATIVO | J4: RES. POSITIVO
A5: 1 | B5: ='LIBRO MAYOR'!D3 -> Fondo Fijo | C5: ='LIBRO MAYOR'!D5 -> 2500000 | E5: =C5 -> 2500000 | G5: =E5 -> 2500000
A6: 2 | B6: ='LIBRO MAYOR'!D11 -> Banco GNB SA CTA CTE | C6: ='LIBRO MAYOR'!D24 -> 631220000 | D6: ='LIBRO MAYOR'!E24 -> 320530000 | E6: =C6-D6 -> 310690000 | G6: =E6 -> 310690000
A7: 3 | B7: ='LIBRO MAYOR'!D26 -> Banco ITAU S.A | C7: ='LIBRO MAYOR'!D31 -> 100000000 | E7: =C7 -> 100000000 | G7: =E7 -> 100000000
A8: 4 | B8: ='LIBRO MAYOR'!D34 -> Documentos a Cobrar | C8: ='LIBRO MAYOR'!D39 -> 135580000 | E8: =C8 -> 135580000 | G8: =E8 -> 135580000
A9: 5 | B9: ='LIBRO MAYOR'!D42 -> Prestamos Bancarios | D9: ='LIBRO MAYOR'!E47 -> 200000000 | F9: =D9 -> 200000000 | H9: =D9 -> 200000000
A10: 6 | B10: Interes a Pagar | D10: ='LIBRO MAYOR'!E55 -> 12328767 | F10: =D10 -> 12328767 | H10: =F10 -> 12328767
A11: 7 | B11: Capital | D11: ='LIBRO MAYOR'!E63 -> 3.4147123e+08 | F11: =D11 -> 3.4147123e+08 | H11: =F11 -> 3.4147123e+08
A12: 8 | B12: Muebles y Equipos | C12: ='LIBRO MAYOR'!D71 -> 2409090.9 | E12: =C12 -> 2409090.9 | G12: =E12 -> 2409090.9
A13: 9 | B13: IVA CF 10% | C13: ='LIBRO MAYOR'!D83 -> 31230000 | E13: =C13 -> 31230000 | G13: =E13 -> 31230000
A14: 10 | B14: ='LIBRO MAYOR'!D87 -> Elementos de Transporte | C14: ='LIBRO MAYOR'!D92 -> 42727273 | E14: =C14 -> 42727273 | G14: =E14 -> 42727273
A15: 11 | B15: ='LIBRO MAYOR'!D95 -> Documentos a Pagar | D15: ='LIBRO MAYOR'!E100 -> 23500000 | F15: =D15 -> 23500000 | H15: =F15 -> 23500000
A16: 12 | B16: ='LIBRO MAYOR'!D104 -> Mercaderias | C16: ='LIBRO MAYOR'!D110 -> 2.6045455e+08 | D16: ='LIBRO MAYOR'!E110 -> 2.4272727e+08 | E16: =C16-D16 -> 17727273 | G16: =E16 -> 17727273
A17: 13 | B17: ='LIBRO MAYOR'!D113 -> Venta de Mercaderias | D17: ='LIBRO MAYOR'!E118 -> 2.8681818e+08 | F17: =D17 -> 2.8681818e+08 | J17: =F17 -> 2.8681818e+08
A18: 14 | B18: ='LIBRO MAYOR'!D120 -> IVA DF 10% | D18: ='LIBRO MAYOR'!E125 -> 28681819 | F18: =D18 -> 28681819 | H18: =F18 -> 28681819
A19: 15 | B19: ='LIBRO MAYOR'!D127 -> Costo de Ventas | C19: ='LIBRO MAYOR'!D132 -> 2.4272727e+08 | E19: =C19 -> 2.4272727e+08 | I19: =C19 -> 2.4272727e+08
A20: 16 | B20: ='LIBRO MAYOR'!D135 -> Tasas, Patentes e Impuestos | C20: ='LIBRO MAYOR'!D140 -> 500000 | E20: =C20 -> 500000 | I20: =E20 -> 500000
A21: 17 | B21: ='LIBRO MAYOR'!D143 -> Gastos de Limpieza | C21: ='LIBRO MAYOR'!D148 -> 1200000 | E21: =C21 -> 1200000 | I21: =E21 -> 1200000
A22: 18 | B22: ='LIBRO MAYOR'!D151 -> Agua, Luz y Telefono | C22: ='LIBRO MAYOR'!D156 -> 890909.09 | E22: =C22 -> 890909.09 | I22: =E22 -> 890909.09
A23: 19 | B23: ='LIBRO MAYOR'!D158 -> Honorarios Profesionales | C23: ='LIBRO MAYOR'!D163 -> 4618181.8 | E23: =C23 -> 4618181.8 | I23: =E23 -> 4618181.8
A24: 20 | B24: ='LIBRO MAYOR'!D165 -> Sueldos y Jornales | C24: ='LIBRO MAYOR'!D170 -> 9180373 | E24: =C24 -> 9180373 | I24: =E24 -> 9180373
A25: 21 | B25: ='LIBRO MAYOR'!D172 -> Aporte Patronal | C25: ='LIBRO MAYOR'!D177 -> 1514761.5 | E25: =C25 -> 1514761.5 | I25: =E25 -> 1514761.5
A26: 22 | B26: IPS a Pagar | D26: ='LIBRO MAYOR'!E184 -> 2340995.1 | F26: =D26 -> 2340995.1 | H26: =F26 -> 2340995.1
A27: 23 | B27: Sueldos a Pagar | D27: ='LIBRO MAYOR'!E191 -> 8354139.4 | F27: =D27 -> 8354139.4 | H27: =F27 -> 8354139.4
B28: SUMAS TOTALES | C28: =SUM(C5:C27) -> 1.4667524e+09 | D28: =SUM(D5:D27) -> 1.4667524e+09 | E28: =SUM(E5:E27) -> 9.0349513e+08 | F28: =SUM(F5:F27) -> 9.0349513e+08 | G28: =SUM(G5:G27) -> 6.4286364e+08 | H28: =SUM(H5:H27) -> 6.1667695e+08 | I28: =SUM(I5:I27) -> 2.606315e+08 | J28: =SUM(J5:J27) -> 2.8681818e+08
B29: RESULTADO DEL EJERCICIO | H29: =I29 -> 26186683 | I29: =J34 -> 26186683
B30: SUMAS IGUALES | C30: =SUM(C28:C29) -> 1.4667524e+09 | D30: =SUM(D28:D29) -> 1.4667524e+09 | E30: =SUM(E28:E29) -> 9.0349513e+08 | F30: =SUM(F28:F29) -> 9.0349513e+08 | G30: =SUM(G28:G29) -> 6.4286364e+08 | H30: =SUM(H28:H29) -> 6.4286364e+08 | I30: =SUM(I28:I29) -> 2.8681818e+08 | J30: =SUM(J28:J29) -> 2.8681818e+08
I32: Resultados Positivos | J32: =J28 -> 2.8681818e+08
I33: Resultados Negativos | J33: =I28 -> 2.606315e+08
I34: Ganancia | J34: =J32-J33 -> 26186683
E35: IRE | F35: =J34*10% -> 2618668.3
E36: LIQUIDEZ | F36: =G28/H28 -> 1.0424642
E37: ENDEUDAMIENTO | F37: =H28/G28 -> 0.95926557
E38: ROI | F38: =(F17-E19)/E19 -> 0.18164794
